Workbook

Sheet Invoice
B5: Invoice Date | C5: : 2026-04-06
B6: Billing Account Name | C6: : Coupang
B7: Term of Use | C7: : 2026-03-01 ~ 2026-03-31
B9: API | C9: Usage | D9: Free Usage | E9: Subtotal | F9: 할인 구간 | H9: 단가 | I9: Amount
B10: Dynamic Maps | C10: 6161 | D10: =SUMIF('GMP Price List'!$A:$A,B10,'GMP Price List'!$C:$C) | E10: =IF(C10-D10>0,C10-D10,0) | F10: 0-100K | G10: =IF(E10>100000,100000,E10) | H10: =SUMIF('GMP Price List'!$A:$A,B10,'GMP Price List'!$D:$D) | I10: =G10*H10/1000
F11: ~500K | G11: =IF(E10>500000,400000,E10-G10) | H11: =SUMIF('GMP Price List'!$A:$A,B10,'GMP Price List'!$E:$E) | I11: =G11*H11/1000
F12: ~1M | G12: =IF(E10>1000000,500000,E10-G10-G11) | H12: =SUMIF('GMP Price List'!$A:$A,B10,'GMP Price List'!$F:$F) | I12: =G12*H12/1000
F13: ~5M | G13: =IF(E10>5000000,4000000,E10-G10-G11-G12) | H13: =SUMIF('GMP Price List'!$A:$A,B10,'GMP Price List'!$G:$G) | I13: =G13*H13/1000
F14: ~10M | G14: =IF(E10-G10-G11-G12-G13>0,E10-G10-G11-G12-G13,0) | H14: =SUMIF('GMP Price List'!$A:$A,B10,'GMP Price List'!$H:$H) | I14: =G14*H14/1000
B15: 소계 | G15: =SUM(G10:G14) | I15: =ROUND(SUM(I10:I14),2)
B16: Directions | C16: 0 | D16: =SUMIF('GMP Price List'!$A:$A,B16,'GMP Price List'!$C:$C) | E16: =IF(C16-D16>0,C16-D16,0) | F16: 0-100K | G16: =IF(E16>100000,100000,E16) | H16: =SUMIF('GMP Price List'!$A:$A,B16,'GMP Price List'!$D:$D) | I16: =G16*H16/1000
F17: ~500K | G17: =IF(E16>500000,400000,E16-G16) | H17: =SUMIF('GMP Price List'!$A:$A,B16,'GMP Price List'!$E:$E) | I17: =G17*H17/1000
F18: ~1M | G18: =IF(E16>1000000,500000,E16-G16-G17) | H18: =SUMIF('GMP Price List'!$A:$A,B16,'GMP Price List'!$F:$F) | I18: =G18*H18/1000
F19: ~5M | G19: =IF(E16>5000000,4000000,E16-G16-G17-G18) | H19: =SUMIF('GMP Price List'!$A:$A,B16,'GMP Price List'!$G:$G) | I19: =G19*H19/1000
F20: ~10M | G20: =IF(E16-G16-G17-G18-G19>0,E16-G16-G17-G18-G19,0) | H20: =SUMIF('GMP Price List'!$A:$A,B16,'GMP Price List'!$H:$H) | I20: =G20*H20/1000
B21: 소계 | G21: =SUM(G16:G20) | I21: =ROUND(SUM(I16:I20),2)
B22: Geocoding | C22: 6520 | D22: =SUMIF('GMP Price List'!$A:$A,B22,'GMP Price List'!$C:$C) | E22: =IF(C22-D22>0,C22-D22,0) | F22: 0-100K | G22: =IF(E22>100000,100000,E22) | H22: =SUMIF('GMP Price List'!$A:$A,B22,'GMP Price List'!$D:$D) | I22: =G22*H22/1000
F23: ~500K | G23: =IF(E22>500000,400000,E22-G22) | H23: =SUMIF('GMP Price List'!$A:$A,B22,'GMP Price List'!$E:$E) | I23: =G23*H23/1000
F24: ~1M | G24: =IF(E22>1000000,500000,E22-G22-G23) | H24: =SUMIF('GMP Price List'!$A:$A,B22,'GMP Price List'!$F:$F) | I24: =G24*H24/1000
F25: ~5M | G25: =IF(E22>5000000,4000000,E22-G22-G23-G24) | H25: =SUMIF('GMP Price List'!$A:$A,B22,'GMP Price List'!$G:$G) | I25: =G25*H25/1000
F26: ~10M | G26: =IF(E22-G22-G23-G24-G25>0,E22-G22-G23-G24-G25,0) | H26: =SUMIF('GMP Price List'!$A:$A,B22,'GMP Price List'!$H:$H) | I26: =G26*H26/1000
B27: 소계 | G27: =SUM(G22:G26) | I27: =ROUND(SUM(I22:I26),2)
B28: Autocomplete - Per Request | C28: 0 | D28: =SUMIF('GMP Price List'!$A:$A,B28,'GMP Price List'!$C:$C) | E28: =IF(C28-D28>0,C28-D28,0) | F28: 0-100K | G28: =IF(E28>100000,100000,E28) | H28: =SUMIF('GMP Price List'!$A:$A,B28,'GMP Price List'!$D:$D) | I28: =G28*H28/1000
F29: ~500K | G29: =IF(E28>500000,400000,E28-G28) | H29: =SUMIF('GMP Price List'!$A:$A,B28,'GMP Price List'!$E:$E) | I29: =G29*H29/1000
F30: ~1M | G30: =IF(E28>1000000,500000,E28-G28-G29) | H30: =SUMIF('GMP Price List'!$A:$A,B28,'GMP Price List'!$F:$F) | I30: =G30*H30/1000
F31: ~5M | G31: =IF(E28>5000000,4000000,E28-G28-G29-G30) | H31: =SUMIF('GMP Price List'!$A:$A,B28,'GMP Price List'!$G:$G) | I31: =G31*H31/1000
F32: ~10M | G32: =IF(E28-G28-G29-G30-G31>0,E28-G28-G29-G30-G31,0) | H32: =SUMIF('GMP Price List'!$A:$A,B28,'GMP Price List'!$H:$H) | I32: =G32*H32/1000
B33: 소계 | G33: =SUM(G28:G32) | I33: =ROUND(SUM(I28:I32),2)
B34: Autocomplete without Places Details - Per Session | C34: 0 | D34: =SUMIF('GMP Price List'!$A:$A,B34,'GMP Price List'!$C:$C) | E34: =IF(C34-D34>0,C34-D34,0) | F34: 0-100K | G34: =IF(E34>100000,100000,E34) | H34: =SUMIF('GMP Price List'!$A:$A,B34,'GMP Price List'!$D:$D) | I34: =G34*H34/1000
F35: ~500K | G35: =IF(E34>500000,400000,E34-G34) | H35: =SUMIF('GMP Price List'!$A:$A,B34,'GMP Price List'!$E:$E) | I35: =G35*H35/1000
F36: ~1M | G36: =IF(E34>1000000,500000,E34-G34-G35) | H36: =SUMIF('GMP Price List'!$A:$A,B34,'GMP Price List'!$F:$F) | I36: =G36*H36/1000
F37: ~5M | G37: =IF(E34>5000000,4000000,E34-G34-G35-G36) | H37: =SUMIF('GMP Price List'!$A:$A,B34,'GMP Price List'!$G:$G) | I37: =G37*H37/1000
F38: ~10M | G38: =IF(E34-G34-G35-G36-G37>0,E34-G34-G35-G36-G37,0) | H38: =SUMIF('GMP Price List'!$A:$A,B34,'GMP Price List'!$H:$H) | I38: =G38*H38/1000
B39: 소계 | G39: =SUM(G34:G38) | I39: =ROUND(SUM(I34:I38),2)
B40: Query Autocomplete - Per Request | C40: 0 | D40: =SUMIF('GMP Price List'!$A:$A,B40,'GMP Price List'!$C:$C) | E40: =IF(C40-D40>0,C40-D40,0) | F40: 0-100K | G40: =IF(E40>100000,100000,E40) | H40: =SUMIF('GMP Price List'!$A:$A,B40,'GMP Price List'!$D:$D) | I40: =G40*H40/1000
F41: ~500K | G41: =IF(E40>500000,400000,E40-G40) | H41: =SUMIF('GMP Price List'!$A:$A,B40,'GMP Price List'!$E:$E) | I41: =G41*H41/1000
F42: ~1M | G42: =IF(E40>1000000,500000,E40-G40-G41) | H42: =SUMIF('GMP Price List'!$A:$A,B40,'GMP Price List'!$F:$F) | I42: =G42*H42/1000
F43: ~5M | G43: =IF(E40>5000000,4000000,E40-G40-G41-G42) | H43: =SUMIF('GMP Price List'!$A:$A,B40,'GMP Price List'!$G:$G) | I43: =G43*H43/1000
F44: ~10M | G44: =IF(E40-G40-G41-G42-G43>0,E40-G40-G41-G42-G43,0) | H44: =SUMIF('GMP Price List'!$A:$A,B40,'GMP Price List'!$H:$H) | I44: =G44*H44/1000
B45: 소계 | G45: =SUM(G40:G44) | I45: =ROUND(SUM(I40:I44),2)
...

Sheet Project
B5: Invoice Date | C5: =Invoice!C5
B6: Billing Account Name | C6: : Coupang
B7: Term of Use | C7: =Invoice!C7
B8: 환율 | C8: =Invoice!I84 | D8: (하나은행 2026.03.31 최종 송금환율 기준)
E9: =SUM(C11,C18,C25,C32,C39,C46) | H9: =SUM(F11,F18,F25,F32,F39,F46) | K9: =SUM(I11,I18,I25,I32,I39,I46) | N9: =SUM(L11,L18,L25,L32,L39,L46) | Q9: =SUM(O11,O18,O25,O32,O39,O46) | T9: =SUM(R11,R18,R25,R32,R39,R46) | W9: =SUM(U11,U18,U25,U32,U39,U46) | Z9: =SUM(X11,X18,X25,X32,X39,X46) | AC9: =SUM(AA11,AA18,AA25,AA32,AA39,AA46) | AF9: =SUM(AD11,AD18,AD25,AD32,AD39,AD46) | AI9: =SUM(AG11,AG18,AG25,AG32,AG39,AG46)
B10: LSMNM | C10: =Invoice!$B$10 | F10: =Invoice!$B$22 | I10: =Invoice!$B$28 | L10: =Invoice!$B$34 | O10: =Invoice!$B$40 | R10: =Invoice!$B$46 | U10: =Invoice!$B$52 | X10: =Invoice!$B$58 | AA10: =Invoice!$B$64 | AD10: =Invoice!$B$70 | AG10: =Invoice!$B$76
C11: 6161 | F11: 6520 | I11: 0 | L11: 0 | O11: 0 | R11: 0 | U11: 0 | X11: 0 | AA11: 0 | AD11: 0 | AG11: 0
C12: monthly unit price($) | E12: amount | F12: monthly unit price($) | H12: amount | I12: monthly unit price($) | K12: amount | L12: monthly unit price($) | N12: amount | O12: monthly unit price($) | Q12: amount | R12: monthly unit price($) | T12: amount | U12: monthly unit price($) | W12: amount | X12: monthly unit price($) | Z12: amount | AA12: monthly unit price($) | AC12: amount | AD12: monthly unit price($) | AF12: amount | AG12: monthly unit price($) | AI12: amount
C13: =Invoice!$I$15/Invoice!$C$10 | E13: =C11*C13 | F13: =Invoice!$I$27/Invoice!$C$22 | H13: =F11*F13 | I13: =Invoice!$I$33/Invoice!$C$28 | K13: =I11*I13 | L13: =IF(Invoice!C34>0,Invoice!$I$39/Invoice!$C$34,0) | N13: =L11*L13 | O13: =Invoice!$I$45/Invoice!$C$40 | Q13: =O11*O13 | R13: =Invoice!$I$51/Invoice!$C$46 | T13: =R11*R13 | U13: =Invoice!$I$57/Invoice!$C$52 | W13: =U11*U13 | X13: =Invoice!$I$63/Invoice!$C$58 | Z13: =X11*X13 | AA13: =Invoice!$I$69/Invoice!$C$64 | AC13: =AA11*AA13 | AD13: =Invoice!$I$75/Invoice!$C$70 | AF13: =AD11*AD13 | AG13: =Invoice!$I$81/Invoice!$C$76 | AI13: =AG11*AG13
B14: toal($) | E14: =ROUND(SUM(E13,H13,K13,N13,Q13,T13,W13,Z13,AC13,AF13,AI13),0)
B15: toal(\) | E15: =ROUND(E14*$C$8,0)
E16: =E13+E20+E27+E34+E41+E48 | H16: =H13+H20+H27+H34+H41+H48 | K16: =K13+K20+K27+K34+K41+K48 | N16: =N13+N20+N27+N34+N41+N48 | Q16: =Q13+Q20+Q27+Q34+Q41+Q48 | T16: =T13+T20+T27+T34+T41+T48 | W16: =W13+W20+W27+W34+W41+W48 | Z16: =Z13+Z20+Z27+Z34+Z41+Z48 | AC16: =AC13+AC20+AC27+AC34+AC41+AC48 | AF16: =AF13+AF20+AF27+AF34+AF41+AF48 | AI16: =AI13+AI20+AI27+AI34+AI41+AI48 | AL16: =AL13+AL20+AL27+AL34+AL41+AL48
B17: Coupang-02 | C17: =Invoice!$B$10 | F17: =Invoice!$B$22 | I17: =Invoice!$B$28 | L17: =Invoice!$B$34 | O17: =Invoice!$B$40 | R17: =Invoice!$B$46 | U17: =Invoice!$B$52 | X17: =Invoice!$B$58 | AA17: =Invoice!$B$64 | AD17: =Invoice!$B$70 | AG17: =Invoice!$B$76 | AJ17: Directions
C18: 6087249 | F18: 0 | I18: 0 | L18: 0 | O18: 0 | R18: 0 | U18: 20 | X18: 20 | AA18: 20 | AD18: 0 | AG18: 20 | AJ18: 0
C19: monthly unit price($) | E19: amount | F19: monthly unit price($) | H19: amount | I19: monthly unit price($) | K19: amount | L19: monthly unit price($) | N19: amount | O19: monthly unit price($) | Q19: amount | R19: monthly unit price($) | T19: amount | U19: monthly unit price($) | W19: amount | X19: monthly unit price($) | Z19: amount | AA19: monthly unit price($) | AC19: amount | AD19: monthly unit price($) | AF19: amount | AG19: monthly unit price($) | AI19: amount | AJ19: monthly unit price($) | AL19: amount
C20: =Invoice!$I$15/Invoice!$C$10 | E20: =C18*C20 | F20: =Invoice!$I$27/Invoice!$C$22 | H20: =F18*F20 | I20: =Invoice!$I$33/Invoice!$C$28 | K20: =I18*I20 | L20: =L13 | N20: =L18*L20 | O20: =Invoice!$I$45/Invoice!$C$40 | Q20: =O18*O20 | R20: =Invoice!$I$51/Invoice!$C$46 | T20: =R18*R20 | U20: =Invoice!$I$57/Invoice!$C$52 | W20: =U18*U20 | X20: =Invoice!$I$63/Invoice!$C$58 | Z20: =X18*X20 | AA20: =Invoice!$I$69/Invoice!$C$64 | AC20: =AA18*AA20 | AD20: =Invoice!$I$75/Invoice!$C$70 | AF20: =AD18*AD20 | AG20: =Invoice!$I$81/Invoice!$C$76 | AI20: =AG18*AG20 | AJ20: =IF(Invoice!C16>0,Invoice!I21/Invoice!C16,0) | AL20: =AJ18*AJ20
B21: toal($) | E21: =ROUND(SUM(E20,H20,K20,N20,Q20,T20,W20,Z20,AC20,AF20,AI20),0)
B22: toal(\) | E22: =ROUND(E21*$C$8,0)
B24: Coupang-03 | C24: =Invoice!$B$10 | F24: =Invoice!$B$22 | I24: =Invoice!$B$28 | L24: =Invoice!$B$34 | O24: =Invoice!$B$40 | R24: =Invoice!$B$46 | U24: =Invoice!$B$52 | X24: =Invoice!$B$58 | AA24: =Invoice!$B$64 | AD24: =Invoice!$B$70 | AG24: =Invoice!$B$76 | AJ24: Directions
F25: 315
C26: monthly unit price($) | E26: amount | F26: monthly unit price($) | H26: amount | I26: monthly unit price($) | K26: amount | L26: monthly unit price($) | N26: amount | O26: monthly unit price($) | Q26: amount | R26: monthly unit price($) | T26: amount | U26: monthly unit price($) | W26: amount | X26: monthly unit price($) | Z26: amount | AA26: monthly unit price($) | AC26: amount | AD26: monthly unit price($) | AF26: amount | AG26: monthly unit price($) | AI26: amount | AJ26: monthly unit price($) | AL26: amount
C27: =Invoice!$I$15/Invoice!$C$10 | E27: =C25*C27 | F27: =Invoice!$I$27/Invoice!$C$22 | H27: =F25*F27 | I27: =Invoice!$I$33/Invoice!$C$28 | K27: =I25*I27 | L27: =L13 | N27: =L25*L27 | O27: =Invoice!$I$45/Invoice!$C$40 | Q27: =O25*O27 | R27: =Invoice!$I$51/Invoice!$C$46 | T27: =R25*R27 | U27: =Invoice!$I$57/Invoice!$C$52 | W27: =U25*U27 | X27: =Invoice!$I$63/Invoice!$C$58 | Z27: =X25*X27 | AA27: =Invoice!$I$69/Invoice!$C$64 | AC27: =AA25*AA27 | AD27: =Invoice!$I$75/Invoice!$C$70 | AF27: =AD25*AD27 | AG27: =Invoice!$I$81/Invoice!$C$76 | AI27: =AG25*AG27 | AJ27: =AJ20 | AL27: =AJ25*AJ27
B28: toal($) | E28: =ROUND(SUM(E27,H27,K27,N27,Q27,T27,W27,Z27,AC27,AF27,AI27),0)
B29: toal(\) | E29: =ROUNDUP(E28*$C$8,0)
B31: Coupang-04 | C31: =Invoice!$B$10 | F31: =Invoice!$B$22 | I31: =Invoice!$B$28 | L31: =Invoice!$B$34 | O31: =Invoice!$B$40 | R31: =Invoice!$B$46 | U31: =Invoice!$B$52 | X31: =Invoice!$B$58 | AA31: =Invoice!$B$64 | AD31: =Invoice!$B$70 | AG31: =Invoice!$B$76
C32: 29945 | F32: 173489 | I32: 11287 | L32: 23 | O32: 0 | R32: 51983 | U32: 61541 | X32: 61541 | AA32: 61541 | AD32: 9556 | AG32: 0
C33: monthly unit price($) | E33: amount | F33: monthly unit price($) | H33: amount | I33: monthly unit price($) | K33: amount | L33: monthly unit price($) | N33: amount | O33: monthly unit price($) | Q33: amount | R33: monthly unit price($) | T33: amount | U33: monthly unit price($) | W33: amount | X33: monthly unit price($) | Z33: amount | AA33: monthly unit price($) | AC33: amount | AD33: monthly unit price($) | AF33: amount | AG33: monthly unit price($) | AI33: amount
C34: =Invoice!$I$15/Invoice!$C$10 | E34: =C32*C34 | F34: =Invoice!$I$27/Invoice!$C$22 | H34: =F32*F34 | I34: =Invoice!$I$33/Invoice!$C$28 | K34: =I32*I34 | L34: =L13 | N34: =L32*L34 | O34: =Invoice!$I$45/Invoice!$C$40 | Q34: =O32*O34 | R34: =Invoice!$I$51/Invoice!$C$46 | T34: =R32*R34 | U34: =Invoice!$I$57/Invoice!$C$52 | W34: =U32*U34 | X34: =Invoice!$I$63/Invoice!$C$58 | Z34: =X32*X34 | AA34: =Invoice!$I$69/Invoice!$C$64 | AC34: =AA32*AA34 | AD34: =Invoice!$I$75/Invoice!$C$70 | AF34: =AD32*AD34 | AG34: =Invoice!$I$81/Invoice!$C$76 | AI34: =AG32*AG34
B35: toal($) | E35: =ROUND(SUM(E34,H34,K34,N34,Q34,T34,W34,Z34,AC34,AF34,AI34),0)
B36: toal(\) | E36: =ROUND(E35*$C$8,0)
B38: Coupang-05 | C38: =Invoice!$B$10 | F38: =Invoice!$B$22 | I38: =Invoice!$B$28 | L38: =Invoice!$B$34 | O38: =Invoice!$B$40 | R38: =Invoice!$B$46 | U38: =Invoice!$B$52 | X38: =Invoice!$B$58 | AA38: =Invoice!$B$64 | AD38: =Invoice!$B$70 | AG38: =Invoice!$B$76
C39: 262 | F39: 680 | I39: 0 | L39: 0 | O39: 1887 | R39: 64 | U39: 250 | X39: 250 | AA39: 250 | AD39: 186 | AG39: 0
C40: monthly unit price($) | E40: amount | F40: monthly unit price($) | H40: amount | I40: monthly unit price($) | K40: amount | L40: monthly unit price($) | N40: amount | O40: monthly unit price($) | Q40: amount | R40: monthly unit price($) | T40: amount | U40: monthly unit price($) | W40: amount | X40: monthly unit price($) | Z40: amount | AA40: monthly unit price($) | AC40: amount | AD40: monthly unit price($) | AF40: amount | AG40: monthly unit price($) | AI40: amount
C41: =Invoice!$I$15/Invoice!$C$10 | E41: =C39*C41 | F41: =Invoice!$I$27/Invoice!$C$22 | H41: =F39*F41 | I41: =Invoice!$I$33/Invoice!$C$28 | K41: =I39*I41 | L41: =L13 | N41: =L39*L41 | O41: =Invoice!$I$45/Invoice!$C$40 | Q41: =O39*O41 | R41: =Invoice!$I$51/Invoice!$C$46 | T41: =R39*R41 | U41: =Invoice!$I$57/Invoice!$C$52 | W41: =U39*U41 | X41: =Invoice!$I$63/Invoice!$C$58 | Z41: =X39*X41 | AA41: =Invoice!$I$69/Invoice!$C$64 | AC41: =AA39*AA41 | AD41: =Invoice!$I$75/Invoice!$C$70 | AF41: =AD39*AD41 | AG41: =Invoice!$I$81/Invoice!$C$76 | AI41: =AG39*AG41
B42: toal($) | E42: =ROUND(SUM(E41,H41,K41,N41,Q41,T41,W41,Z41,AC41,AF41,AI41),0)
B43: toal(\) | E43: =ROUND(E42*$C$8,0)
B45: Butter - Google Search API | C45: =Invoice!$B$10 | F45: =Invoice!$B$22 | I45: =Invoice!$B$28 | L45: =Invoice!$B$34 | O45: =Invoice!$B$40 | R45: =Invoice!$B$46 | U45: =Invoice!$B$52 | X45: =Invoice!$B$58 | AA45: =Invoice!$B$64 | AD45: =Invoice!$B$70 | AG45: =Invoice!$B$76
C46: 0 | F46: 0 | I46: 0 | L46: 0 | O46: 0 | R46: 0 | U46: 0 | X46: 0 | AA46: 0 | AD46: 0 | AG46: 0
C47: monthly unit price($) | E47: amount | F47: monthly unit price($) | H47: amount | I47: monthly unit price($) | K47: amount | L47: monthly unit price($) | N47: amount | O47: monthly unit price($) | Q47: amount | R47: monthly unit price($) | T47: amount | U47: monthly unit price($) | W47: amount | X47: monthly unit price($) | Z47: amount | AA47: monthly unit price($) | AC47: amount | AD47: monthly unit price($) | AF47: amount | AG47: monthly unit price($) | AI47: amount
C48: =Invoice!$I$15/Invoice!$C$10 | E48: =C46*C48 | F48: =Invoice!$I$27/Invoice!$C$22 | H48: =F46*F48 | I48: =Invoice!$I$33/Invoice!$C$28 | K48: =I46*I48 | L48: =L13 | N48: =L46*L48 | O48: =Invoice!$I$45/Invoice!$C$40 | Q48: =O46*O48 | R48: =Invoice!$I$51/Invoice!$C$46 | T48: =R46*R48 | U48: =Invoice!$I$57/Invoice!$C$52 | W48: =U46*U48 | X48: =Invoice!$I$63/Invoice!$C$58 | Z48: =X46*X48 | AA48: =Invoice!$I$69/Invoice!$C$64 | AC48: =AA46*AA48 | AD48: =Invoice!$I$75/Invoice!$C$70 | AF48: =AD46*AD48 | AG48: =Invoice!$I$81/Invoice!$C$76 | AI48: =AG46*AG48
...

Sheet GMP Price List
A2: Maps
D3: COST PER THOUSAND (CPM)
A4: Monthly volume range | B4: Category | C4: Free Usage Cap¹ | D4: Free usage cap to 100,000 | E4: 100,001 to 500,000 | F4: 500,001 to 1,000,000 | G4: 1,000,001 to 5,000,000 | H4: 5,000,001 to 10,000,000 | I4: 10,000,000 +
A5: Embed | B5: Essentials | C5: Unlimited | D5: 0 | E5: 0 | F5: 0 | G5: 0 | H5: 0 | I5: 별도문의
A6: Maps SDK | B6: Essentials | C6: Unlimited | D6: 0 | E6: 0 | F6: 0 | G6: 0 | H6: 0 | I6: 별도문의
A7: Street View Metadata | B7: Essentials | C7: Unlimited | D7: 0 | E7: 0 | F7: 0 | G7: 0 | H7: 0 | I7: 별도문의
A8: Dynamic Maps | B8: Essentials | C8: 10000 | D8: 7 | E8: 5.6 | F8: 4.2 | G8: 2.1 | H8: 0.53 | I8: 별도문의
A9: Static Maps | B9: Essentials | C9: 10000 | D9: 2 | E9: 1.6 | F9: 1.2 | G9: 0.6 | H9: 0.15 | I9: 별도문의
A10: Static Street View | B10: Essentials | C10: 10000 | D10: 7 | E10: 5.6 | F10: 4.2 | G10: 2.1 | H10: 0.53 | I10: 별도문의
A11: Aerial View | B11: Pro | C11: 5000 | D11: 16 | E11: 12.8 | F11: 9.6 | G11: 4.8 | H11: 1.2 | I11: 별도문의
A12: Dynamic Street View | B12: Pro | C12: 5000 | D12: 14 | E12: 11.2 | F12: 8.4 | G12: 4.2 | H12: 1.05 | I12: 별도문의
A13: Elevation | B13: Pro | C13: 5000 | D13: 5 | E13: 4 | F13: 3 | G13: 1.5 | H13: 0.38 | I13: 별도문의
A16: Map Tiles
D17: COST PER THOUSAND (CPM)
A18: Monthly volume range | B18: Category | C18: Free Usage Cap¹ | D18: Free usage cap to 1,000,000 | E18: 1,000,001 to 5,000,000 | F18: 5,000,001 to 10,000,000 | G18: 10,000,001 to 50,000,000 | H18: 5,000,001 to 10,000,000 | I18: 10,000,000 +
A19: Map Tiles API: 2D Map Tiles | B19: Essentials | C19: 100000 | D19: 0.6 | E19: 0.48 | F19: 0.36 | G19: 0.18 | H19: 0.045 | I19: 별도문의
A20: Map Tiles API: Street View Tiles | B20: Essentials | C20: 100000 | D20: 2 | E20: 1.6 | F20: 1.2 | G20: 0.6 | H20: 0.2 | I20: 별도문의
D22: COST PER THOUSAND (CPM)
A23: Monthly volume range | B23: Category | C23: Free Usage Cap¹ | D23: Free usage cap to 100,000 | E23: 100,001 to 500,000 | F23: 500,001 to 1,000,000 | G23: 1,000,001 to 5,000,000 | H23: 5,000,001 to 10,000,000 | I23: 10,000,000 +
A24: Map Tiles API: Photorealistic 3D Tiles | B24: Enterprise | C24: 1000 | D24: 6 | E24: 5.1 | F24: 4.2 | G24: 3.3 | H24: 2.4 | I24: 별도문의
A27: Routes
D28: COST PER THOUSAND (CPM)
A29: Monthly volume range | B29: Category | C29: Free Usage Cap¹ | D29: Free usage cap to 100,000 | E29: 100,001 to 500,000 | F29: 500,001 to 1,000,000 | G29: 1,000,001 to 5,000,000 | H29: 5,000,001 to 10,000,000 | I29: 10,000,000 +
A30: Routes: Compute Route Matrix Essentials | B30: Essentials | C30: 10000 | D30: 5 | E30: 4 | F30: 3 | G30: 1.5 | H30: 0.38 | I30: 별도문의
A31: Routes: Compute Routes Essentials | B31: Essentials | C31: 10000 | D31: 5 | E31: 4 | F31: 3 | G31: 1.5 | H31: 0.38 | I31: 별도문의
A32: Roads - Nearest Road | B32: Pro | C32: 5000 | D32: 10 | E32: 8 | F32: 6 | G32: 3 | H32: 0.76 | I32: 별도문의
A33: Roads - Route Traveled | B33: Pro | C33: 5000 | D33: 10 | E33: 8 | F33: 6 | G33: 3 | H33: 0.76 | I33: 별도문의
A34: Roads - Speed Limits² | B34: Pro | C34: 5000 | D34: 20 | E34: 16 | F34: 12 | G34: 12 | H34: 12 | I34: 별도문의
A35: RouteOptimization - SingleVehicleRouting | B35: Pro | C35: 5000 | D35: 10 | E35: 4 | F35: 2 | G35: 0.8 | H35: 0.7 | I35: 별도문의
A36: Routes: Compute Route Matrix Pro | B36: Pro | C36: 5000 | D36: 10 | E36: 8 | F36: 6 | G36: 3 | H36: 0.75 | I36: 별도문의
A37: Routes: Compute Routes Pro | B37: Pro | C37: 5000 | D37: 10 | E37: 8 | F37: 6 | G37: 3 | H37: 0.75 | I37: 별도문의
A38: RouteOptimization - FleetRouting | B38: Enterprise | C38: 1000 | D38: 30 | E38: 14 | F38: 6 | G38: 2.4 | H38: 2.1 | I38: 별도문의
A39: Routes: Compute Route Matrix Enterprise | B39: Enterprise | C39: 1000 | D39: 15 | E39: 12 | F39: 9 | G39: 4.5 | H39: 1.14 | I39: 별도문의
A40: Routes: Compute Routes Enterprise | B40: Enterprise | C40: 1000 | D40: 15 | E40: 12 | F40: 9 | G40: 4.5 | H40: 1.14 | I40: 별도문의
A42: Monthly volume range | C42: Free Usage Cap¹ | D42: Free usage cap to 4,200,000 destinations | E42: 4,200,000 to 16,800,000 destinations | F42: 16,800,000 +
A43: Navigation Request | B43: Enterprise | C43: 1000 | D43: 50 | E43: 39.5 | F43: 28
A46: Places
D47: COST PER THOUSAND (CPM)
A48: Monthly volume range | B48: Category | C48: Free Usage Cap¹ | D48: Free usage cap to 100,000 | E48: 100,001 to 500,000 | F48: 500,001 to 1,000,000 | G48: 1,000,001 to 5,000,000 | H48: 5,000,001 to 10,000,000 | I48: 10,000,000 +
A49: Autocomplete Session Usage | B49: Essentials | C49: Unlimited | D49: 0 | E49: 0 | F49: 0 | G49: 0 | H49: 0 | I49: 별도문의
...
