Workbook

Sheet Invoice
B5: Invoice Date | C5: : 2026-04-06
B6: Billing Account Name | C6: lotte-card
B7: Term of Use | C7: 2026-02-28 ~ 2026-03-31
B9: API | C9: Usage | D9: Free Usage | E9: Subtotal | F9: 할인 구간 | H9: 단가 | I9: Amount
B10: Dynamic Maps | C10: 5581 | D10: =SUMIF('GMP Price List'!$A:$A,B10,'GMP Price List'!$C:$C) | E10: =IF(C10-D10>0,C10-D10,0) | F10: 0-100K | G10: =IF(E10>100000,100000,E10) | H10: =SUMIF('GMP Price List'!$A:$A,B10,'GMP Price List'!$D:$D) | I10: =G10*H10/1000
F11: ~500K | G11: =IF(E10>500000,400000,E10-G10) | H11: =SUMIF('GMP Price List'!$A:$A,B10,'GMP Price List'!$E:$E) | I11: =G11*H11/1000
F12: ~1M | G12: =IF(E10>1000000,500000,E10-G10-G11) | H12: =SUMIF('GMP Price List'!$A:$A,B10,'GMP Price List'!$F:$F) | I12: =G12*H12/1000
F13: ~5M | G13: =IF(E10>5000000,4000000,E10-G10-G11-G12) | H13: =SUMIF('GMP Price List'!$A:$A,B10,'GMP Price List'!$G:$G) | I13: =G13*H13/1000
F14: ~10M | G14: =IF(E10-G10-G11-G12-G13>0,E10-G10-G11-G12-G13,0) | H14: =SUMIF('GMP Price List'!$A:$A,B10,'GMP Price List'!$H:$H) | I14: =G14*H14/1000
B15: 소계 | G15: =SUM(G10:G14) | I15: =ROUND(SUM(I10:I14),2)
B16: Directions | C16: 0 | D16: =SUMIF('GMP Price List'!$A:$A,B16,'GMP Price List'!$C:$C) | E16: =IF(C16-D16>0,C16-D16,0) | F16: 0-100K | G16: =IF(E16>100000,100000,E16) | H16: =SUMIF('GMP Price List'!$A:$A,B16,'GMP Price List'!$D:$D) | I16: =G16*H16/1000
F17: ~500K | G17: =IF(E16>500000,400000,E16-G16) | H17: =SUMIF('GMP Price List'!$A:$A,B16,'GMP Price List'!$E:$E) | I17: =G17*H17/1000
F18: ~1M | G18: =IF(E16>1000000,500000,E16-G16-G17) | H18: =SUMIF('GMP Price List'!$A:$A,B16,'GMP Price List'!$F:$F) | I18: =G18*H18/1000
F19: ~5M | G19: =IF(E16>5000000,4000000,E16-G16-G17-G18) | H19: =SUMIF('GMP Price List'!$A:$A,B16,'GMP Price List'!$G:$G) | I19: =G19*H19/1000
F20: ~10M | G20: =IF(E16-G16-G17-G18-G19>0,E16-G16-G17-G18-G19,0) | H20: =SUMIF('GMP Price List'!$A:$A,B16,'GMP Price List'!$H:$H) | I20: =G20*H20/1000
B21: 소계 | G21: =SUM(G16:G20) | I21: =ROUND(SUM(I16:I20),2)
B22: Geocoding | C22: 1759 | D22: =SUMIF('GMP Price List'!$A:$A,B22,'GMP Price List'!$C:$C) | E22: =IF(C22-D22>0,C22-D22,0) | F22: 0-100K | G22: =IF(E22>100000,100000,E22) | H22: =SUMIF('GMP Price List'!$A:$A,B22,'GMP Price List'!$D:$D) | I22: =G22*H22/1000
F23: ~500K | G23: =IF(E22>500000,400000,E22-G22) | H23: =SUMIF('GMP Price List'!$A:$A,B22,'GMP Price List'!$E:$E) | I23: =G23*H23/1000
F24: ~1M | G24: =IF(E22>1000000,500000,E22-G22-G23) | H24: =SUMIF('GMP Price List'!$A:$A,B22,'GMP Price List'!$F:$F) | I24: =G24*H24/1000
F25: ~5M | G25: =IF(E22>5000000,4000000,E22-G22-G23-G24) | H25: =SUMIF('GMP Price List'!$A:$A,B22,'GMP Price List'!$G:$G) | I25: =G25*H25/1000
F26: ~10M | G26: =IF(E22-G22-G23-G24-G25>0,E22-G22-G23-G24-G25,0) | H26: =SUMIF('GMP Price List'!$A:$A,B22,'GMP Price List'!$H:$H) | I26: =G26*H26/1000
B27: 소계 | G27: =SUM(G22:G26) | I27: =ROUND(SUM(I22:I26),2)
B28: Autocomplete - Per Request | C28: 0 | D28: =SUMIF('GMP Price List'!$A:$A,B28,'GMP Price List'!$C:$C) | E28: =IF(C28-D28>0,C28-D28,0) | F28: 0-100K | G28: =IF(E28>100000,100000,E28) | H28: =SUMIF('GMP Price List'!$A:$A,B28,'GMP Price List'!$D:$D) | I28: =G28*H28/1000
F29: ~500K | G29: =IF(E28>500000,400000,E28-G28) | H29: =SUMIF('GMP Price List'!$A:$A,B28,'GMP Price List'!$E:$E) | I29: =G29*H29/1000
F30: ~1M | G30: =IF(E28>1000000,500000,E28-G28-G29) | H30: =SUMIF('GMP Price List'!$A:$A,B28,'GMP Price List'!$F:$F) | I30: =G30*H30/1000
F31: ~5M | G31: =IF(E28>5000000,4000000,E28-G28-G29-G30) | H31: =SUMIF('GMP Price List'!$A:$A,B28,'GMP Price List'!$G:$G) | I31: =G31*H31/1000
F32: ~10M | G32: =IF(E28-G28-G29-G30-G31>0,E28-G28-G29-G30-G31,0) | H32: =SUMIF('GMP Price List'!$A:$A,B28,'GMP Price List'!$H:$H) | I32: =G32*H32/1000
B33: 소계 | G33: =SUM(G28:G32) | I33: =ROUND(SUM(I28:I32),2)
B34: Autocomplete without Places Details - Per Session | C34: 0 | D34: =SUMIF('GMP Price List'!$A:$A,B34,'GMP Price List'!$C:$C) | E34: =IF(C34-D34>0,C34-D34,0) | F34: 0-100K | G34: =IF(E34>100000,100000,E34) | H34: =SUMIF('GMP Price List'!$A:$A,B34,'GMP Price List'!$D:$D) | I34: =G34*H34/1000
F35: ~500K | G35: =IF(E34>500000,400000,E34-G34) | H35: =SUMIF('GMP Price List'!$A:$A,B34,'GMP Price List'!$E:$E) | I35: =G35*H35/1000
F36: ~1M | G36: =IF(E34>1000000,500000,E34-G34-G35) | H36: =SUMIF('GMP Price List'!$A:$A,B34,'GMP Price List'!$F:$F) | I36: =G36*H36/1000
F37: ~5M | G37: =IF(E34>5000000,4000000,E34-G34-G35-G36) | H37: =SUMIF('GMP Price List'!$A:$A,B34,'GMP Price List'!$G:$G) | I37: =G37*H37/1000
F38: ~10M | G38: =IF(E34-G34-G35-G36-G37>0,E34-G34-G35-G36-G37,0) | H38: =SUMIF('GMP Price List'!$A:$A,B34,'GMP Price List'!$H:$H) | I38: =G38*H38/1000
B39: 소계 | G39: =SUM(G34:G38) | I39: =ROUND(SUM(I34:I38),2)
B40: Query Autocomplete - Per Request | C40: 0 | D40: =SUMIF('GMP Price List'!$A:$A,B40,'GMP Price List'!$C:$C) | E40: =IF(C40-D40>0,C40-D40,0) | F40: 0-100K | G40: =IF(E40>100000,100000,E40) | H40: =SUMIF('GMP Price List'!$A:$A,B40,'GMP Price List'!$D:$D) | I40: =G40*H40/1000
F41: ~500K | G41: =IF(E40>500000,400000,E40-G40) | H41: =SUMIF('GMP Price List'!$A:$A,B40,'GMP Price List'!$E:$E) | I41: =G41*H41/1000
F42: ~1M | G42: =IF(E40>1000000,500000,E40-G40-G41) | H42: =SUMIF('GMP Price List'!$A:$A,B40,'GMP Price List'!$F:$F) | I42: =G42*H42/1000
F43: ~5M | G43: =IF(E40>5000000,4000000,E40-G40-G41-G42) | H43: =SUMIF('GMP Price List'!$A:$A,B40,'GMP Price List'!$G:$G) | I43: =G43*H43/1000
F44: ~10M | G44: =IF(E40-G40-G41-G42-G43>0,E40-G40-G41-G42-G43,0) | H44: =SUMIF('GMP Price List'!$A:$A,B40,'GMP Price List'!$H:$H) | I44: =G44*H44/1000
B45: 소계 | G45: =SUM(G40:G44) | I45: =ROUND(SUM(I40:I44),2)
...

Sheet Project
B5: Invoice Date | C5: =Invoice!C5
B6: Billing Account Name | C6: lotte-card
B7: Term of Use | C7: 2026-02-28 ~ 2026-03-31
B8: 환율 | C8: =Invoice!I84 | D8: (하나은행 2026.03.31 최종 송금환율 기준)
E9: =SUM(#REF!,#REF!,#REF!,#REF!,#REF!,#REF!) | H9: =SUM(#REF!,#REF!,#REF!,#REF!,#REF!,#REF!) | K9: =SUM(#REF!,#REF!,#REF!,#REF!,#REF!,#REF!) | N9: =SUM(#REF!,#REF!,#REF!,#REF!,#REF!,#REF!) | Q9: =SUM(#REF!,#REF!,#REF!,#REF!,#REF!,#REF!) | T9: =SUM(#REF!,#REF!,#REF!,#REF!,#REF!,#REF!) | W9: =SUM(#REF!,#REF!,#REF!,#REF!,#REF!,#REF!) | Z9: =SUM(#REF!,#REF!,#REF!,#REF!,#REF!,#REF!) | AC9: =SUM(#REF!,#REF!,#REF!,#REF!,#REF!,#REF!) | AF9: =SUM(#REF!,#REF!,#REF!,#REF!,#REF!,#REF!) | AI9: =SUM(#REF!,#REF!,#REF!,#REF!,#REF!,#REF!)
B11: lotte-card

Sheet GMP Price List
A2: Maps
D3: COST PER THOUSAND (CPM)
A4: Monthly volume range | B4: Category | C4: Free Usage Cap¹ | D4: Free usage cap to 100,000 | E4: 100,001 to 500,000 | F4: 500,001 to 1,000,000 | G4: 1,000,001 to 5,000,000 | H4: 5,000,001 to 10,000,000 | I4: 10,000,000 +
A5: Embed | B5: Essentials | C5: Unlimited | D5: 0 | E5: 0 | F5: 0 | G5: 0 | H5: 0 | I5: 별도문의
A6: Maps SDK | B6: Essentials | C6: Unlimited | D6: 0 | E6: 0 | F6: 0 | G6: 0 | H6: 0 | I6: 별도문의
A7: Street View Metadata | B7: Essentials | C7: Unlimited | D7: 0 | E7: 0 | F7: 0 | G7: 0 | H7: 0 | I7: 별도문의
A8: Dynamic Maps | B8: Essentials | C8: 10000 | D8: 7 | E8: 5.6 | F8: 4.2 | G8: 2.1 | H8: 0.53 | I8: 별도문의
A9: Static Maps | B9: Essentials | C9: 10000 | D9: 2 | E9: 1.6 | F9: 1.2 | G9: 0.6 | H9: 0.15 | I9: 별도문의
A10: Static Street View | B10: Essentials | C10: 10000 | D10: 7 | E10: 5.6 | F10: 4.2 | G10: 2.1 | H10: 0.53 | I10: 별도문의
A11: Aerial View | B11: Pro | C11: 5000 | D11: 16 | E11: 12.8 | F11: 9.6 | G11: 4.8 | H11: 1.2 | I11: 별도문의
A12: Dynamic Street View | B12: Pro | C12: 5000 | D12: 14 | E12: 11.2 | F12: 8.4 | G12: 4.2 | H12: 1.05 | I12: 별도문의
A13: Elevation | B13: Pro | C13: 5000 | D13: 5 | E13: 4 | F13: 3 | G13: 1.5 | H13: 0.38 | I13: 별도문의
A16: Map Tiles
D17: COST PER THOUSAND (CPM)
A18: Monthly volume range | B18: Category | C18: Free Usage Cap¹ | D18: Free usage cap to 1,000,000 | E18: 1,000,001 to 5,000,000 | F18: 5,000,001 to 10,000,000 | G18: 10,000,001 to 50,000,000 | H18: 5,000,001 to 10,000,000 | I18: 10,000,000 +
A19: Map Tiles API: 2D Map Tiles | B19: Essentials | C19: 100000 | D19: 0.6 | E19: 0.48 | F19: 0.36 | G19: 0.18 | H19: 0.045 | I19: 별도문의
A20: Map Tiles API: Street View Tiles | B20: Essentials | C20: 100000 | D20: 2 | E20: 1.6 | F20: 1.2 | G20: 0.6 | H20: 0.2 | I20: 별도문의
D22: COST PER THOUSAND (CPM)
A23: Monthly volume range | B23: Category | C23: Free Usage Cap¹ | D23: Free usage cap to 100,000 | E23: 100,001 to 500,000 | F23: 500,001 to 1,000,000 | G23: 1,000,001 to 5,000,000 | H23: 5,000,001 to 10,000,000 | I23: 10,000,000 +
A24: Map Tiles API: Photorealistic 3D Tiles | B24: Enterprise | C24: 1000 | D24: 6 | E24: 5.1 | F24: 4.2 | G24: 3.3 | H24: 2.4 | I24: 별도문의
A27: Routes
D28: COST PER THOUSAND (CPM)
A29: Monthly volume range | B29: Category | C29: Free Usage Cap¹ | D29: Free usage cap to 100,000 | E29: 100,001 to 500,000 | F29: 500,001 to 1,000,000 | G29: 1,000,001 to 5,000,000 | H29: 5,000,001 to 10,000,000 | I29: 10,000,000 +
A30: Routes: Compute Route Matrix Essentials | B30: Essentials | C30: 10000 | D30: 5 | E30: 4 | F30: 3 | G30: 1.5 | H30: 0.38 | I30: 별도문의
A31: Routes: Compute Routes Essentials | B31: Essentials | C31: 10000 | D31: 5 | E31: 4 | F31: 3 | G31: 1.5 | H31: 0.38 | I31: 별도문의
A32: Roads - Nearest Road | B32: Pro | C32: 5000 | D32: 10 | E32: 8 | F32: 6 | G32: 3 | H32: 0.76 | I32: 별도문의
A33: Roads - Route Traveled | B33: Pro | C33: 5000 | D33: 10 | E33: 8 | F33: 6 | G33: 3 | H33: 0.76 | I33: 별도문의
A34: Roads - Speed Limits² | B34: Pro | C34: 5000 | D34: 20 | E34: 16 | F34: 12 | G34: 12 | H34: 12 | I34: 별도문의
A35: RouteOptimization - SingleVehicleRouting | B35: Pro | C35: 5000 | D35: 10 | E35: 4 | F35: 2 | G35: 0.8 | H35: 0.7 | I35: 별도문의
A36: Routes: Compute Route Matrix Pro | B36: Pro | C36: 5000 | D36: 10 | E36: 8 | F36: 6 | G36: 3 | H36: 0.75 | I36: 별도문의
A37: Routes: Compute Routes Pro | B37: Pro | C37: 5000 | D37: 10 | E37: 8 | F37: 6 | G37: 3 | H37: 0.75 | I37: 별도문의
A38: RouteOptimization - FleetRouting | B38: Enterprise | C38: 1000 | D38: 30 | E38: 14 | F38: 6 | G38: 2.4 | H38: 2.1 | I38: 별도문의
A39: Routes: Compute Route Matrix Enterprise | B39: Enterprise | C39: 1000 | D39: 15 | E39: 12 | F39: 9 | G39: 4.5 | H39: 1.14 | I39: 별도문의
A40: Routes: Compute Routes Enterprise | B40: Enterprise | C40: 1000 | D40: 15 | E40: 12 | F40: 9 | G40: 4.5 | H40: 1.14 | I40: 별도문의
A42: Monthly volume range | C42: Free Usage Cap¹ | D42: Free usage cap to 4,200,000 destinations | E42: 4,200,000 to 16,800,000 destinations | F42: 16,800,000 +
A43: Navigation Request | B43: Enterprise | C43: 1000 | D43: 50 | E43: 39.5 | F43: 28
A46: Places
D47: COST PER THOUSAND (CPM)
A48: Monthly volume range | B48: Category | C48: Free Usage Cap¹ | D48: Free usage cap to 100,000 | E48: 100,001 to 500,000 | F48: 500,001 to 1,000,000 | G48: 1,000,001 to 5,000,000 | H48: 5,000,001 to 10,000,000 | I48: 10,000,000 +
A49: Autocomplete Session Usage | B49: Essentials | C49: Unlimited | D49: 0 | E49: 0 | F49: 0 | G49: 0 | H49: 0 | I49: 별도문의
...
